<sdf version='1.7'>
  <model name='car'>
    <link name='base_link'>
      <inertial>
        <pose>-7e-06 -4e-06 -1e-06 0 -0 0</pose>
        <mass>3.5656</mass>
        <inertia>
          <ixx>0.0087493</ixx>
          <ixy>-1.66866e-06</ixy>
          <ixz>-4.49975e-07</ixz>
          <iyy>0.044049</iyy>
          <iyz>-2.40287e-07</iyz>
          <izz>0.0505139</izz>
        </inertia>
      </inertial>
      <collision name='base_link_collision_collision'>
        <pose>0 0 0 0 -0 0</pose>
        <geometry>
          <box>
            <size>0.01 0.01 0.001</size>
          </box>
        </geometry>
      </collision>
      <collision name='base_link_fixed_joint_lump__chassis_collision_collision_1'>
        <pose>0 0 0 0 -0 0</pose>
        <geometry>
          <box>
            <size>0.38 0.16 0.062</size>
          </box>
        </geometry>
        <surface>
          <contact>
            <ode/>
          </contact>
          <friction>
            <ode/>
          </friction>
        </surface>
      </collision>
      <collision name='base_link_fixed_joint_lump__right_rear_shock_mount_column_collision_collision_2'>
        <pose>-0.125 -0.058 -0.018 0 0 -1.5708</pose>
        <geometry>
          <cylinder>
            <length>0.0483</length>
            <radius>0.002</radius>
          </cylinder>
        </geometry>
      </collision>
      <collision name='base_link_fixed_joint_lump__right_rear_axle_collision_collision_3'>
        <pose>-0.125 -0.0755 -0.018 1.5708 1.5708 0</pose>
        <geometry>
          <cylinder>
            <length>0.035</length>
            <radius>0.00166</radius>
          </cylinder>
        </geometry>
      </collision>
      <visual name='base_link_visual'>
        <pose>0 0 0 0 -0 0</pose>
        <geometry>
          <box>
            <size>0.01 0.01 0.001</size>
          </box>
        </geometry>
      </visual>
      <visual name='base_link_fixed_joint_lump__chassis_visual_1'>
        <pose>0 0 0 0 -0 0</pose>
        <geometry>
          <box>
            <size>0.38 0.16 0.062</size>
          </box>
        </geometry>
        <material>
          <script>
            <name>Gazebo/White</name>
            <uri>file://media/materials/scripts/gazebo.material</uri>
          </script>
        </material>
      </visual>
      <visual name='base_link_fixed_joint_lump__right_rear_shock_mount_column_visual_2'>
        <pose>-0.125 -0.058 -0.018 0 0 -1.5708</pose>
        <geometry>
          <cylinder>
            <length>0.0483</length>
            <radius>0.002</radius>
          </cylinder>
        </geometry>
      </visual>
      <visual name='base_link_fixed_joint_lump__right_rear_axle_visual_3'>
        <pose>-0.125 -0.0755 -0.018 1.5708 1.5708 0</pose>
        <geometry>
          <cylinder>
            <length>0.035</length>
            <radius>0.00166</radius>
          </cylinder>
        </geometry>
      </visual>
    </link>
    <joint name='right_rear_to_right_rear_axle_joint' type='revolute'>
      <pose relative_to='base_link'>-0.125 -0.08 -0.018 1.5708 1.5708 0</pose>
      <parent>base_link</parent>
      <child>right_rear</child>
      <axis>
        <xyz>0 0 1</xyz>
        <limit>
          <lower>-1.57</lower>
          <upper>1.57</upper>
          <effort>100</effort>
          <velocity>1</velocity>
        </limit>
        <dynamics>
          <damping>0.1</damping>
          <friction>0.1</friction>
          <spring_reference>0</spring_reference>
          <spring_stiffness>0</spring_stiffness>
        </dynamics>
      </axis>
    </joint>
    <link name='right_rear'>
      <pose relative_to='right_rear_to_right_rear_axle_joint'>0 0 0 0 -0 0</pose>
      <inertial>
        <pose>0 0 0 0 -0 0</pose>
        <mass>0.0282</mass>
        <inertia>
          <ixx>6.30446e-06</ixx>
          <ixy>0</ixy>
          <ixz>0</ixz>
          <iyy>6.30446e-06</iyy>
          <iyz>0</iyz>
          <izz>9.90172e-06</izz>
        </inertia>
      </inertial>
      <collision name='right_rear_fixed_joint_lump__wheel_collision_collision'>
        <pose>0 0 0 0 -0 0</pose>
        <geometry>
          <cylinder>
            <length>0.024</length>
            <radius>0.0265</radius>
          </cylinder>
        </geometry>
      </collision>
      <visual name='right_rear_visual'>
        <pose>0 0 0 0 -0 0</pose>
        <geometry>
          <cylinder>
            <length>0.024</length>
            <radius>0.0265</radius>
          </cylinder>
        </geometry>
        <material>
          <script>
            <name>Gazebo/Black</name>
            <uri>file://media/materials/scripts/gazebo.material</uri>
          </script>
        </material>
      </visual>
    </link>
    <plugin name='gazebo_ros_control' filename='libgazebo_ros_control.so'>
      <robotNamespace>/car</robotNamespace>
      <robotSimType>gazebo_ros_control/DefaultRobotHWSim</robotSimType>
      <legacyModeNS>1</legacyModeNS>
    </plugin>
    <frame name='right_rear_axle_to_right_rear_shock_mount_column_joint' attached_to='right_rear_shock_mount_column'>
      <pose>0.0175 0 0 3.14159 1.57079 3.14159</pose>
    </frame>
    <frame name='right_rear_axle' attached_to='right_rear_axle_to_right_rear_shock_mount_column_joint'/>
    <frame name='chassis_to_right_rear_shock_mount_column_joint' attached_to='chassis'>
      <pose>-0.125 -0.058 -0.018 0 0 -1.5708</pose>
    </frame>
    <frame name='right_rear_shock_mount_column' attached_to='chassis_to_right_rear_shock_mount_column_joint'/>
    <frame name='base_to_chassis_joint' attached_to='base_link'>
      <pose>0 0 0 0 -0 0</pose>
    </frame>
    <frame name='chassis' attached_to='base_to_chassis_joint'/>
  </model>
</sdf>
