<?xml version="1.0"?>
<robot name="positional_jointed_robot">
    <link name="base_link">
        <visual>
            <geometry>
                <box size="0.5 0.3 0.1"/>
            </geometry>
            <material name="blue">
                <color rgba="0 0 0.8 1"/>
            </material>
        </visual>
        <collision>
            <geometry>
                <box size="0.5 0.3 0.1"/>
            </geometry>
        </collision>
        <inertial>
            <mass value="1"/>
            <inertia ixx="0.01" ixy="0" ixz="0" iyy="0.01" iyz="0" izz="0.01"/>
        </inertial>
    </link>

    <link name="arm">
        <visual>
            <geometry>
                <cylinder length="0.4" radius="0.05"/>
            </geometry>
            <material name="red">
                <color rgba="0.8 0 0 1"/>
            </material>
        </visual>
        <collision>
            <geometry>
                <cylinder length="0.4" radius="0.05"/>
            </geometry>
        </collision>
        <inertial>
            <mass value="0.5"/>
            <inertia ixx="0.01" ixy="0" ixz="0" iyy="0.01" iyz="0" izz="0.005"/>
        </inertial>
    </link>

    <joint name="base_to_arm" type="revolute">
        <parent link="base_link"/>
        <child link="arm"/>
        <origin xyz="0.25 0 0.2" rpy="0 0 0"/>
        <axis xyz="0 0 1"/>
        <limit lower="-1.57" upper="1.57" effort="100" velocity="1"/>
        <dynamics damping="0.1" friction="0.1"/>
    </joint>

    <transmission name="arm_trans">
        <type>transmission_interface/SimpleTransmission</type>
        <joint name="base_to_arm">
            <hardwareInterface>hardware_interface/PositionJointInterface</hardwareInterface>
        </joint>
        <actuator name="arm_motor">
            <hardwareInterface>hardware_interface/PositionJointInterface</hardwareInterface>
            <mechanicalReduction>1</mechanicalReduction>
        </actuator>
    </transmission>

    <gazebo>
        <plugin name="gazebo_ros_control" filename="libgazebo_ros_control.so">
            <robotNamespace>/positional_jointed_robot</robotNamespace>
        </plugin>
    </gazebo>
</robot>